Workbook
Name PM_cdf_Y: 'SIPmath Chart Data'!$A$322:$A$426
Name PM_DfltBins: 10
Name PM_Index: PMTable!$A$1
Name PM_InitialVariableID: 976994
Name PM_library_file_name: "ISAR Sample_risk_calculator (1).xlsx"
Name PM_library_file_path: "C:\Users\Sam Savage\Documents\Alex Sidorenko"
Name PM_local_library: TRUE
Name PM_MaxBins: 100
Name PM_random_mode: TRUE
Name PM_Risk_1_axis_lbls: OFFSET( 'SIPmath Chart Data'!$B$219:$B$320, 0, 0, 'SIPmath Chart Data'!$B$6 )
Name PM_Risk_1_bins: 'SIPmath Chart Data'!$B$14:$B$114
Name PM_Risk_1_freq: 'SIPmath Chart Data'!$B$116:$B$217
Name PM_Risk_1_hist_data: OFFSET( 'SIPmath Chart Data'!$B$116:$B$217, 0, 0, 'SIPmath Chart Data'!$B$6 )
Name PM_Risk_1_lbls: 'SIPmath Chart Data'!$B$219:$B$320
Name PM_Risk_10_axis_lbls: OFFSET( 'SIPmath Chart Data'!$K$219:$K$320, 0, 0, 'SIPmath Chart Data'!$K$6 )
Name PM_Risk_10_bins: 'SIPmath Chart Data'!$K$14:$K$114
Name PM_Risk_10_freq: 'SIPmath Chart Data'!$K$116:$K$217
Name PM_Risk_10_hist_data: OFFSET( 'SIPmath Chart Data'!$K$116:$K$217, 0, 0, 'SIPmath Chart Data'!$K$6 )
Name PM_Risk_10_lbls: 'SIPmath Chart Data'!$K$219:$K$320
Name PM_Risk_2_axis_lbls: OFFSET( 'SIPmath Chart Data'!$C$219:$C$320, 0, 0, 'SIPmath Chart Data'!$C$6 )
Name PM_Risk_2_bins: 'SIPmath Chart Data'!$C$14:$C$114
Name PM_Risk_2_freq: 'SIPmath Chart Data'!$C$116:$C$217
Name PM_Risk_2_hist_data: OFFSET( 'SIPmath Chart Data'!$C$116:$C$217, 0, 0, 'SIPmath Chart Data'!$C$6 )
Name PM_Risk_2_lbls: 'SIPmath Chart Data'!$C$219:$C$320
Name PM_Risk_3_axis_lbls: OFFSET( 'SIPmath Chart Data'!$D$219:$D$320, 0, 0, 'SIPmath Chart Data'!$D$6 )
Name PM_Risk_3_bins: 'SIPmath Chart Data'!$D$14:$D$114
Name PM_Risk_3_freq: 'SIPmath Chart Data'!$D$116:$D$217
Name PM_Risk_3_hist_data: OFFSET( 'SIPmath Chart Data'!$D$116:$D$217, 0, 0, 'SIPmath Chart Data'!$D$6 )
Name PM_Risk_3_lbls: 'SIPmath Chart Data'!$D$219:$D$320
Name PM_Risk_4_axis_lbls: OFFSET( 'SIPmath Chart Data'!$E$219:$E$320, 0, 0, 'SIPmath Chart Data'!$E$6 )
Name PM_Risk_4_bins: 'SIPmath Chart Data'!$E$14:$E$114
Name PM_Risk_4_freq: 'SIPmath Chart Data'!$E$116:$E$217
Name PM_Risk_4_hist_data: OFFSET( 'SIPmath Chart Data'!$E$116:$E$217, 0, 0, 'SIPmath Chart Data'!$E$6 )
Name PM_Risk_4_lbls: 'SIPmath Chart Data'!$E$219:$E$320
Name PM_Risk_5_axis_lbls: OFFSET( 'SIPmath Chart Data'!$F$219:$F$320, 0, 0, 'SIPmath Chart Data'!$F$6 )
Name PM_Risk_5_bins: 'SIPmath Chart Data'!$F$14:$F$114
Name PM_Risk_5_freq: 'SIPmath Chart Data'!$F$116:$F$217
Name PM_Risk_5_hist_data: OFFSET( 'SIPmath Chart Data'!$F$116:$F$217, 0, 0, 'SIPmath Chart Data'!$F$6 )
Name PM_Risk_5_lbls: 'SIPmath Chart Data'!$F$219:$F$320
Name PM_Risk_6_axis_lbls: OFFSET( 'SIPmath Chart Data'!$G$219:$G$320, 0, 0, 'SIPmath Chart Data'!$G$6 )
Name PM_Risk_6_bins: 'SIPmath Chart Data'!$G$14:$G$114
Name PM_Risk_6_freq: 'SIPmath Chart Data'!$G$116:$G$217
Name PM_Risk_6_hist_data: OFFSET( 'SIPmath Chart Data'!$G$116:$G$217, 0, 0, 'SIPmath Chart Data'!$G$6 )
Name PM_Risk_6_lbls: 'SIPmath Chart Data'!$G$219:$G$320
Name PM_Risk_7_axis_lbls: OFFSET( 'SIPmath Chart Data'!$H$219:$H$320, 0, 0, 'SIPmath Chart Data'!$H$6 )
Name PM_Risk_7_bins: 'SIPmath Chart Data'!$H$14:$H$114
Name PM_Risk_7_freq: 'SIPmath Chart Data'!$H$116:$H$217
Name PM_Risk_7_hist_data: OFFSET( 'SIPmath Chart Data'!$H$116:$H$217, 0, 0, 'SIPmath Chart Data'!$H$6 )
Name PM_Risk_7_lbls: 'SIPmath Chart Data'!$H$219:$H$320
Name PM_Risk_8_axis_lbls: OFFSET( 'SIPmath Chart Data'!$I$219:$I$320, 0, 0, 'SIPmath Chart Data'!$I$6 )
Name PM_Risk_8_bins: 'SIPmath Chart Data'!$I$14:$I$114
Name PM_Risk_8_freq: 'SIPmath Chart Data'!$I$116:$I$217
Name PM_Risk_8_hist_data: OFFSET( 'SIPmath Chart Data'!$I$116:$I$217, 0, 0, 'SIPmath Chart Data'!$I$6 )
Name PM_Risk_8_lbls: 'SIPmath Chart Data'!$I$219:$I$320
Name PM_Risk_9_axis_lbls: OFFSET( 'SIPmath Chart Data'!$J$219:$J$320, 0, 0, 'SIPmath Chart Data'!$J$6 )
Name PM_Risk_9_bins: 'SIPmath Chart Data'!$J$14:$J$114
Name PM_Risk_9_freq: 'SIPmath Chart Data'!$J$116:$J$217
Name PM_Risk_9_hist_data: OFFSET( 'SIPmath Chart Data'!$J$116:$J$217, 0, 0, 'SIPmath Chart Data'!$J$6 )
Name PM_Risk_9_lbls: 'SIPmath Chart Data'!$J$219:$J$320
Name PM_Total_axis_lbls: OFFSET( 'SIPmath Chart Data'!$L$219:$L$320, 0, 0, 'SIPmath Chart Data'!$L$6 )

Sheet Описание
A5: Краткое описание модели количественной оценки рисков

Sheet Риск_калькулятор
F1: Шаблон реестра рисков с использованием имитационного моделирования | O1: HDR 0/1 | P1: HDR Triang
B2: Var ID 0/1 | C2: Var ID Triang | D2: № | E2: Название риска | F2: Вероятность | G2: Размер ущерба | J2: Моделирование | K2: Среднее значение | L2: Лимит для риска | M2: Персентиль | N2: Вероятность превышения лимита
G3: Минимальный | H3: Ожидаемый | I3: Максимальный | M3: 0.95
B4: техническая ячейка | C4: техническая ячейка | D4: номер риска для графиков | E4: описание риска, возможно добавить описание причин и последствий | F4: экспертная оценка вероятности наступления рискового события в заданный период, обычно 1 год или горизонт проекта или планирования | G4: минимальная граница ущерба | H4: наиболее вероятный ушерб в случае реализации риска | I4: максимальная граница ущерба | J4: результаты имитационного моделирования, распределение. Вероятность моделируется с помощью распределения бернули, ушерб с помощью треугольного | K4: среднее значение ущерба по результатам моделирования | L4: уровень толерантности к каждому риску | M4: значение, не выше которого будет ущерб от риска в ХХ% случаев. ХХ% устанавливается выше. 1-ХХ% вероятность, что ущерб будет больше | N4: Вероятность того, что ушерб от риска будет выше уровня толератности данного риска
A5: =IFERROR(_xlfn.RANK.EQ($K5,$K$5:$K$14,0),"") -> 3 | B5: 1001 | C5: 2001 | D5: R1 | E5: Техническая неисправность оборудования | F5: 0.9 | G5: 10 | H5: 50 | I5: 70 | J5: =F17*G17 -> 61.316919 | K5: =AVERAGE(Risk_1) -> 38.85898 | L5: 100 | M5: =PERCENTILE(Risk_1,$M$3) -> 61.843839 | N5: =COUNTIF( Risk_1, ">" & L5 ) / PM_Trials -> 0 | O5: =( MOD((( MOD( (B5+1000000)^2 + (B5+1000000)*(PM_Index+10000000), 99999989 )) + 1000007 ) * (( MOD( (PM_Index+10000000)^2 + (PM_Index+10000000) * ( MOD( (B5+1000000)^2 + (B5+1000000)*(PM_Index+10000000), 99999989 )), 99999989 )) + 1000013 ), 2147483647 ) + 0.5 ) / 2147483647 -> 0.5119209 | P5: =( MOD((( MOD( (976984+1000000)^2 + (976984+1000000)*(PM_Index+10000000), 99999989 )) + 1000007 ) * (( MOD( (PM_Index+10000000)^2 + (PM_Index+10000000) * ( MOD( (976984+1000000)^2 + (976984+1000000)*(PM_Index+10000000), 99999989 )), 99999989 )) + 1000013 ), 2147483647 ) + 0.5 ) / 2147483647 -> 0.93717008
A6: =IFERROR(_xlfn.RANK.EQ($K6,$K$5:$K$14,0),"") -> 2 | B6: 1002 | C6: 2002 | D6: R2 | E6: Уход ключевого персонала | F6: 0.85 | G6: 50 | H6: 70 | I6: 100 | J6: =F18*G18 -> 0 | K6: =AVERAGE(Risk_2) -> 62.832175 | L6: 70 | M6: =PERCENTILE(Risk_2,$M$3) -> 91.025129 | N6: =COUNTIF( Risk_2, ">" & L6 ) / PM_Trials -> 0.529 | O6: =( MOD((( MOD( (B6+1000000)^2 + (B6+1000000)*(PM_Index+10000000), 99999989 )) + 1000007 ) * (( MOD( (PM_Index+10000000)^2 + (PM_Index+10000000) * ( MOD( (B6+1000000)^2 + (B6+1000000)*(PM_Index+10000000), 99999989 )), 99999989 )) + 1000013 ), 2147483647 ) + 0.5 ) / 2147483647 -> 0.87004898 | P6: =( MOD((( MOD( (976985+1000000)^2 + (976985+1000000)*(PM_Index+10000000), 99999989 )) + 1000007 ) * (( MOD( (PM_Index+10000000)^2 + (PM_Index+10000000) * ( MOD( (976985+1000000)^2 + (976985+1000000)*(PM_Index+10000000), 99999989 )), 99999989 )) + 1000013 ), 2147483647 ) + 0.5 ) / 2147483647 -> 0.42715581
A7: =IFERROR(_xlfn.RANK.EQ($K7,$K$5:$K$14,0),"") -> 1 | B7: 1003 | C7: 2003 | D7: R3 | E7: Недостижение показателей по привлечению средств установленный в срок | F7: 0.7 | G7: 60 | H7: 80 | I7: 150 | J7: =F19*G19 -> 90.70199 | K7: =AVERAGE(Risk_3) -> 67.883669 | L7: 30 | M7: =PERCENTILE(Risk_3,$M$3) -> 127.56466 | N7: =COUNTIF( Risk_3, ">" & L7 ) / PM_Trials -> 0.704 | O7: =( MOD((( MOD( (B7+1000000)^2 + (B7+1000000)*(PM_Index+10000000), 99999989 )) + 1000007 ) * (( MOD( (PM_Index+10000000)^2 + (PM_Index+10000000) * ( MOD( (B7+1000000)^2 + (B7+1000000)*(PM_Index+10000000), 99999989 )), 99999989 )) + 1000013 ), 2147483647 ) + 0.5 ) / 2147483647 -> 0.60655325 | P7: =( MOD((( MOD( (976986+1000000)^2 + (976986+1000000)*(PM_Index+10000000), 99999989 )) + 1000007 ) * (( MOD( (PM_Index+10000000)^2 + (PM_Index+10000000) * ( MOD( (976986+1000000)^2 + (976986+1000000)*(PM_Index+10000000), 99999989 )), 99999989 )) + 1000013 ), 2147483647 ) + 0.5 ) / 2147483647 -> 0.44186444
A8: =IFERROR(_xlfn.RANK.EQ($K8,$K$5:$K$14,0),"") -> 5 | B8: 1004 | C8: 2004 | D8: R4 | E8: Risk 4 | F8: 0.8 | G8: 10 | H8: 50 | I8: 70 | J8: =F20*G20 -> 0 | K8: =AVERAGE(Risk_4) -> 35.099611 | L8: 20 | M8: =PERCENTILE(Risk_4,$M$3) -> 61.183355 | N8: =COUNTIF( Risk_4, ">" & L8 ) / PM_Trials -> 0.78 | O8: =( MOD((( MOD( (B8+1000000)^2 + (B8+1000000)*(PM_Index+10000000), 99999989 )) + 1000007 ) * (( MOD( (PM_Index+10000000)^2 + (PM_Index+10000000) * ( MOD( (B8+1000000)^2 + (B8+1000000)*(PM_Index+10000000), 99999989 )), 99999989 )) + 1000013 ), 2147483647 ) + 0.5 ) / 2147483647 -> 0.88763827 | P8: =( MOD((( MOD( (976987+1000000)^2 + (976987+1000000)*(PM_Index+10000000), 99999989 )) + 1000007 ) * (( MOD( (PM_Index+10000000)^2 + (PM_Index+10000000) * ( MOD( (976987+1000000)^2 + (976987+1000000)*(PM_Index+10000000), 99999989 )), 99999989 )) + 1000013 ), 2147483647 ) + 0.5 ) / 2147483647 -> 0.74026038
A9: =IFERROR(_xlfn.RANK.EQ($K9,$K$5:$K$14,0),"") -> 9 | B9: 1005 | C9: 2005 | D9: R5 | E9: Risk 5 | F9: 0.1 | G9: 10 | H9: 50 | I9: 70 | J9: =F21*G21 -> 0 | K9: =AVERAGE(Risk_5) -> 4.5730083 | L9: 80 | M9: =PERCENTILE(Risk_5,$M$3) -> 46.397165 | N9: =COUNTIF( Risk_5, ">" & L9 ) / PM_Trials -> 0 | O9: =( MOD((( MOD( (B9+1000000)^2 + (B9+1000000)*(PM_Index+10000000), 99999989 )) + 1000007 ) * (( MOD( (PM_Index+10000000)^2 + (PM_Index+10000000) * ( MOD( (B9+1000000)^2 + (B9+1000000)*(PM_Index+10000000), 99999989 )), 99999989 )) + 1000013 ), 2147483647 ) + 0.5 ) / 2147483647 -> 0.99126729 | P9: =( MOD((( MOD( (976988+1000000)^2 + (976988+1000000)*(PM_Index+10000000), 99999989 )) + 1000007 ) * (( MOD( (PM_Index+10000000)^2 + (PM_Index+10000000) * ( MOD( (976988+1000000)^2 + (976988+1000000)*(PM_Index+10000000), 99999989 )), 99999989 )) + 1000013 ), 2147483647 ) + 0.5 ) / 2147483647 -> 0.96564158
A10: =IFERROR(_xlfn.RANK.EQ($K10,$K$5:$K$14,0),"") -> 7 | B10: 1006 | C10: 2006 | D10: R6 | E10: Risk 6 | F10: 0.25 | G10: 10 | H10: 50 | I10: 70 | J10: =F22*G22 -> 0 | K10: =AVERAGE(Risk_6) -> 10.024147 | L10: 60 | M10: =PERCENTILE(Risk_6,$M$3) -> 53.86684 | N10: =COUNTIF( Risk_6, ">" & L10 ) / PM_Trials -> 0.022 | O10: =( MOD((( MOD( (B10+1000000)^2 + (B10+1000000)*(PM_Index+10000000), 99999989 )) + 1000007 ) * (( MOD( (PM_Index+10000000)^2 + (PM_Index+10000000) * ( MOD( (B10+1000000)^2 + (B10+1000000)*(PM_Index+10000000), 99999989 )), 99999989 )) + 1000013 ), 2147483647 ) + 0.5 ) / 2147483647 -> 0.91667555 | P10: =( MOD((( MOD( (976989+1000000)^2 + (976989+1000000)*(PM_Index+10000000), 99999989 )) + 1000007 ) * (( MOD( (PM_Index+10000000)^2 + (PM_Index+10000000) * ( MOD( (976989+1000000)^2 + (976989+1000000)*(PM_Index+10000000), 99999989 )), 99999989 )) + 1000013 ), 2147483647 ) + 0.5 ) / 2147483647 -> 0.71292375
A11: =IFERROR(_xlfn.RANK.EQ($K11,$K$5:$K$14,0),"") -> 6 | B11: 1007 | C11: 2007 | D11: R7 | E11: Risk 7 | F11: 0.45 | G11: 10 | H11: 50 | I11: 70 | J11: =F23*G23 -> 0 | K11: =AVERAGE(Risk_7) -> 18.481278 | L11: 50 | M11: =PERCENTILE(Risk_7,$M$3) -> 58.835777 | N11: =COUNTIF( Risk_7, ">" & L11 ) / PM_Trials -> 0.149 | O11: =( MOD((( MOD( (B11+1000000)^2 + (B11+1000000)*(PM_Index+10000000), 99999989 )) + 1000007 ) * (( MOD( (PM_Index+10000000)^2 + (PM_Index+10000000) * ( MOD( (B11+1000000)^2 + (B11+1000000)*(PM_Index+10000000), 99999989 )), 99999989 )) + 1000013 ), 2147483647 ) + 0.5 ) / 2147483647 -> 0.67858205 | P11: =( MOD((( MOD( (976990+1000000)^2 + (976990+1000000)*(PM_Index+10000000), 99999989 )) + 1000007 ) * (( MOD( (PM_Index+10000000)^2 + (PM_Index+10000000) * ( MOD( (976990+1000000)^2 + (976990+1000000)*(PM_Index+10000000), 99999989 )), 99999989 )) + 1000013 ), 2147483647 ) + 0.5 ) / 2147483647 -> 0.68878132
A12: =IFERROR(_xlfn.RANK.EQ($K12,$K$5:$K$14,0),"") -> 8 | B12: 1008 | C12: 2008 | D12: R8 | E12: Risk 8 | F12: 0.2 | G12: 10 | H12: 50 | I12: 70 | J12: =F24*G24 -> 0 | K12: =AVERAGE(Risk_8) -> 8.2142449 | L12: 30 | M12: =PERCENTILE(Risk_8,$M$3) -> 51.055165 | N12: =COUNTIF( Risk_8, ">" & L12 ) / PM_Trials -> 0.156 | O12: =( MOD((( MOD( (B12+1000000)^2 + (B12+1000000)*(PM_Index+10000000), 99999989 )) + 1000007 ) * (( MOD( (PM_Index+10000000)^2 + (PM_Index+10000000) * ( MOD( (B12+1000000)^2 + (B12+1000000)*(PM_Index+10000000), 99999989 )), 99999989 )) + 1000013 ), 2147483647 ) + 0.5 ) / 2147483647 -> 0.65525302 | P12: =( MOD((( MOD( (976991+1000000)^2 + (976991+1000000)*(PM_Index+10000000), 99999989 )) + 1000007 ) * (( MOD( (PM_Index+10000000)^2 + (PM_Index+10000000) * ( MOD( (976991+1000000)^2 + (976991+1000000)*(PM_Index+10000000), 99999989 )), 99999989 )) + 1000013 ), 2147483647 ) + 0.5 ) / 2147483647 -> 0.9813075
A13: =IFERROR(_xlfn.RANK.EQ($K13,$K$5:$K$14,0),"") -> 4 | B13: 1009 | C13: 2009 | D13: R9 | E13: Risk 9 | F13: 0.8 | G13: 10 | H13: 50 | I13: 70 | J13: =F25*G25 -> 0 | K13: =AVERAGE(Risk_9) -> 35.735753 | L13: 40 | M13: =PERCENTILE(Risk_9,$M$3) -> 61.666064 | N13: =COUNTIF( Risk_9, ">" & L13 ) / PM_Trials -> 0.53 | O13: =( MOD((( MOD( (B13+1000000)^2 + (B13+1000000)*(PM_Index+10000000), 99999989 )) + 1000007 ) * (( MOD( (PM_Index+10000000)^2 + (PM_Index+10000000) * ( MOD( (B13+1000000)^2 + (B13+1000000)*(PM_Index+10000000), 99999989 )), 99999989 )) + 1000013 ), 2147483647 ) + 0.5 ) / 2147483647 -> 0.82692537 | P13: =( MOD((( MOD( (976992+1000000)^2 + (976992+1000000)*(PM_Index+10000000), 99999989 )) + 1000007 ) * (( MOD( (PM_Index+10000000)^2 + (PM_Index+10000000) * ( MOD( (976992+1000000)^2 + (976992+1000000)*(PM_Index+10000000), 99999989 )), 99999989 )) + 1000013 ), 2147483647 ) + 0.5 ) / 2147483647 -> 0.114417
A14: =IFERROR(_xlfn.RANK.EQ($K14,$K$5:$K$14,0),"") -> 10 | B14: 1010 | C14: 2010 | D14: R10 | E14: Risk 10 | F14: 0.1 | G14: 10 | H14: 50 | I14: 70 | J14: =F26*G26 -> 0 | K14: =AVERAGE(Risk_10) -> 4.1725151 | L14: 10 | M14: =PERCENTILE(Risk_10,$M$3) -> 44.484793 | N14: =COUNTIF( Risk_10, ">" & L14 ) / PM_Trials -> 0.094 | O14: =( MOD((( MOD( (B14+1000000)^2 + (B14+1000000)*(PM_Index+10000000), 99999989 )) + 1000007 ) * (( MOD( (PM_Index+10000000)^2 + (PM_Index+10000000) * ( MOD( (B14+1000000)^2 + (B14+1000000)*(PM_Index+10000000), 99999989 )), 99999989 )) + 1000013 ), 2147483647 ) + 0.5 ) / 2147483647 -> 0.61368463 | P14: =( MOD((( MOD( (976993+1000000)^2 + (976993+1000000)*(PM_Index+10000000), 99999989 )) + 1000007 ) * (( MOD( (PM_Index+10000000)^2 + (PM_Index+10000000) * ( MOD( (976993+1000000)^2 + (976993+1000000)*(PM_Index+10000000), 99999989 )), 99999989 )) + 1000013 ), 2147483647 ) + 0.5 ) / 2147483647 -> 0.60848342
B16: Ячейки для ввода данных | F16: It Happened | G16: Impact
E17: Risk 1 | F17: =IF(O5<F5,1,0) -> 1 | G17: =IF( G5 > H5, NA(), IF( H5 > I5, NA(), IF( G5 = I5, H5, IF( P5 < (( H5 - G5 ) / ( I5 - G5 )), G5 + SQRT( P5 * ( H5 - G5 ) * ( I5 - G5 )), I5 - SQRT(( 1 - P5 ) * ( I5 - G5 ) * ( I5 - H5 )))))) -> 61.316919
E18: Risk 2 | F18: =IF(O6<F6,1,0) -> 0 | G18: =IF( G6 > H6, NA(), IF( H6 > I6, NA(), IF( G6 = I6, H6, IF( P6 < (( H6 - G6 ) / ( I6 - G6 )), G6 + SQRT( P6 * ( H6 - G6 ) * ( I6 - G6 )), I6 - SQRT(( 1 - P6 ) * ( I6 - G6 ) * ( I6 - H6 )))))) -> 70.686756
E19: Risk 3 | F19: =IF(O7<F7,1,0) -> 1 | G19: =IF( G7 > H7, NA(), IF( H7 > I7, NA(), IF( G7 = I7, H7, IF( P7 < (( H7 - G7 ) / ( I7 - G7 )), G7 + SQRT( P7 * ( H7 - G7 ) * ( I7 - G7 )), I7 - SQRT(( 1 - P7 ) * ( I7 - G7 ) * ( I7 - H7 )))))) -> 90.70199
E20: Risk 4 | F20: =IF(O8<F8,1,0) -> 0 | G20: =IF( G8 > H8, NA(), IF( H8 > I8, NA(), IF( G8 = I8, H8, IF( P8 < (( H8 - G8 ) / ( I8 - G8 )), G8 + SQRT( P8 * ( H8 - G8 ) * ( I8 - G8 )), I8 - SQRT(( 1 - P8 ) * ( I8 - G8 ) * ( I8 - H8 )))))) -> 52.345325
E21: Risk 5 | F21: =IF(O9<F9,1,0) -> 0 | G21: =IF( G9 > H9, NA(), IF( H9 > I9, NA(), IF( G9 = I9, H9, IF( P9 < (( H9 - G9 ) / ( I9 - G9 )), G9 + SQRT( P9 * ( H9 - G9 ) * ( I9 - G9 )), I9 - SQRT(( 1 - P9 ) * ( I9 - G9 ) * ( I9 - H9 )))))) -> 63.578933
E22: Risk 6 | F22: =IF(O10<F10,1,0) -> 0 | G22: =IF( G10 > H10, NA(), IF( H10 > I10, NA(), IF( G10 = I10, H10, IF( P10 < (( H10 - G10 ) / ( I10 - G10 )), G10 + SQRT( P10 * ( H10 - G10 ) * ( I10 - G10 )), I10 - SQRT(( 1 - P10 ) * ( I10 - G10 ) * ( I10 - H10 )))))) -> 51.439518
E23: Risk 7 | F23: =IF(O11<F11,1,0) -> 0 | G23: =IF( G11 > H11, NA(), IF( H11 > I11, NA(), IF( G11 = I11, H11, IF( P11 < (( H11 - G11 ) / ( I11 - G11 )), G11 + SQRT( P11 * ( H11 - G11 ) * ( I11 - G11 )), I11 - SQRT(( 1 - P11 ) * ( I11 - G11 ) * ( I11 - H11 )))))) -> 50.674824
E24: Risk 8 | F24: =IF(O12<F12,1,0) -> 0 | G24: =IF( G12 > H12, NA(), IF( H12 > I12, NA(), IF( G12 = I12, H12, IF( P12 < (( H12 - G12 ) / ( I12 - G12 )), G12 + SQRT( P12 * ( H12 - G12 ) * ( I12 - G12 )), I12 - SQRT(( 1 - P12 ) * ( I12 - G12 ) * ( I12 - H12 )))))) -> 65.263863
E25: Risk 9 | F25: =IF(O13<F13,1,0) -> 0 | G25: =IF( G13 > H13, NA(), IF( H13 > I13, NA(), IF( G13 = I13, H13, IF( P13 < (( H13 - G13 ) / ( I13 - G13 )), G13 + SQRT( P13 * ( H13 - G13 ) * ( I13 - G13 )), I13 - SQRT(( 1 - P13 ) * ( I13 - G13 ) * ( I13 - H13 )))))) -> 26.571083
E26: Risk 10 | F26: =IF(O14<F14,1,0) -> 0 | G26: =IF( G14 > H14, NA(), IF( H14 > I14, NA(), IF( G14 = I14, H14, IF( P14 < (( H14 - G14 ) / ( I14 - G14 )), G14 + SQRT( P14 * ( H14 - G14 ) * ( I14 - G14 )), I14 - SQRT(( 1 - P14 ) * ( I14 - G14 ) * ( I14 - H14 )))))) -> 48.21466

Sheet Графики
B2: Риски по степени влияния | S2: Шкала вероятности | W2: Шкала ущерба
B3: № | C3: Название риска | D3: Риск-среднее | T3: > | U3: < | X3: > | Y3: <
A4: 1 | B4: =IFERROR(VLOOKUP(A4,Риск_калькулятор!$A$5:$E$14,2,FALSE),"") -> 1003 | C4: =IFERROR(VLOOKUP($B4,Риск_калькулятор!$B$5:$E$14,4,0),"") -> Недостижение показателей по привлечению средств установленный в срок | D4: =IFERROR(VLOOKUP($B4,Риск_калькулятор!$B$5:$K$14,10,0),"") -> 67.883669 | S4: 1 | T4: 0 | U4: 0.1 | W4: 1 | X4: 0 | Y4: =X5 -> 30
A5: 2 | B5: =IFERROR(VLOOKUP(A5,Риск_калькулятор!$A$5:$E$14,2,FALSE),"") -> 1002 | C5: =IFERROR(VLOOKUP($B5,Риск_калькулятор!$B$5:$E$14,4,0),"") -> Уход ключевого персонала | D5: =IFERROR(VLOOKUP($B5,Риск_калькулятор!$B$5:$K$14,10,0),"") -> 62.832175 | S5: 2 | T5: =U4 -> 0.1 | U5: 0.4 | W5: 2 | X5: 30 | Y5: =X6 -> 70
A6: 3 | B6: =IFERROR(VLOOKUP(A6,Риск_калькулятор!$A$5:$E$14,2,FALSE),"") -> 1001 | C6: =IFERROR(VLOOKUP($B6,Риск_калькулятор!$B$5:$E$14,4,0),"") -> Техническая неисправность оборудования | D6: =IFERROR(VLOOKUP($B6,Риск_калькулятор!$B$5:$K$14,10,0),"") -> 38.85898 | S6: 3 | T6: =U5 -> 0.4 | U6: 0.6 | W6: 3 | X6: 70 | Y6: =X7 -> 110
A7: 4 | B7: =IFERROR(VLOOKUP(A7,Риск_калькулятор!$A$5:$E$14,2,FALSE),"") -> 1009 | C7: =IFERROR(VLOOKUP($B7,Риск_калькулятор!$B$5:$E$14,4,0),"") -> Risk 9 | D7: =IFERROR(VLOOKUP($B7,Риск_калькулятор!$B$5:$K$14,10,0),"") -> 35.735753 | S7: 4 | T7: =U6 -> 0.6 | U7: 0.8 | W7: 4 | X7: 110 | Y7: =X8 -> 150
A8: 5 | B8: =IFERROR(VLOOKUP(A8,Риск_калькулятор!$A$5:$E$14,2,FALSE),"") -> 1004 | C8: =IFERROR(VLOOKUP($B8,Риск_калькулятор!$B$5:$E$14,4,0),"") -> Risk 4 | D8: =IFERROR(VLOOKUP($B8,Риск_калькулятор!$B$5:$K$14,10,0),"") -> 35.099611 | S8: 5 | T8: =U7 -> 0.8 | U8: 1 | W8: 5 | X8: 150
A9: 6 | B9: =IFERROR(VLOOKUP(A9,Риск_калькулятор!$A$5:$E$14,2,FALSE),"") -> 1007 | C9: =IFERROR(VLOOKUP($B9,Риск_калькулятор!$B$5:$E$14,4,0),"") -> Risk 7 | D9: =IFERROR(VLOOKUP($B9,Риск_калькулятор!$B$5:$K$14,10,0),"") -> 18.481278
A10: 7 | B10: =IFERROR(VLOOKUP(A10,Риск_калькулятор!$A$5:$E$14,2,FALSE),"") -> 1006 | C10: =IFERROR(VLOOKUP($B10,Риск_калькулятор!$B$5:$E$14,4,0),"") -> Risk 6 | D10: =IFERROR(VLOOKUP($B10,Риск_калькулятор!$B$5:$K$14,10,0),"") -> 10.024147
A11: 8 | B11: =IFERROR(VLOOKUP(A11,Риск_калькулятор!$A$5:$E$14,2,FALSE),"") -> 1008 | C11: =IFERROR(VLOOKUP($B11,Риск_калькулятор!$B$5:$E$14,4,0),"") -> Risk 8 | D11: =IFERROR(VLOOKUP($B11,Риск_калькулятор!$B$5:$K$14,10,0),"") -> 8.2142449
A12: 9 | B12: =IFERROR(VLOOKUP(A12,Риск_калькулятор!$A$5:$E$14,2,FALSE),"") -> 1005 | C12: =IFERROR(VLOOKUP($B12,Риск_калькулятор!$B$5:$E$14,4,0),"") -> Risk 5 | D12: =IFERROR(VLOOKUP($B12,Риск_калькулятор!$B$5:$K$14,10,0),"") -> 4.5730083
A13: 10 | B13: =IFERROR(VLOOKUP(A13,Риск_калькулятор!$A$5:$E$14,2,FALSE),"") -> 1010 | C13: =IFERROR(VLOOKUP($B13,Риск_калькулятор!$B$5:$E$14,4,0),"") -> Risk 10 | D13: =IFERROR(VLOOKUP($B13,Риск_калькулятор!$B$5:$K$14,10,0),"") -> 4.1725151
A14: =IFERROR(_xlfn.RANK.EQ(Риск_калькулятор!$K16,Риск_калькулятор!$K$5:$K$23),"") | B14: =IFERROR(INDEX(Риск_калькулятор!$D$5:$D$14,MATCH(Графики!$A14,Риск_калькулятор!#REF!,0)),"") | C14: =IFERROR(VLOOKUP($B14,Риск_калькулятор!$D$5:$E$14,2,0),"")
A15: =IFERROR(_xlfn.RANK.EQ(Риск_калькулятор!$K17,Риск_калькулятор!$K$5:$K$23),"") | B15: Ячейки для ввода данных
D16: Вероятность | E16: Ущерб | F16: Идентификатор квадранта | J16: x | K16: y
C17: =Риск_калькулятор!D5 -> R1 | D17: =IF(AND(Риск_калькулятор!F5>$T$5,Риск_калькулятор!F5<$U$5),2,IF(AND(Риск_калькулятор!F5>$T$6,Риск_калькулятор!F5<$U$6),3,IF(AND(Риск_калькулятор!F5>$T$7,Риск_калькулятор!F5<$U$7),4,IF(Риск_калькулятор!F5>$T$8,5,1)))) -> 5 | E17: =IF(AND(Риск_калькулятор!M5>$X$5,Риск_калькулятор!M5<$Y$5),2,IF(AND(Риск_калькулятор!M5>$X$6,Риск_калькулятор!M5<$Y$6),3,IF(AND(Риск_калькулятор!M5>$X$7,Риск_калькулятор!M5<$Y$7),4,IF(Риск_калькулятор!M5>$X$8,5,1)))) -> 2 | F17: =D17*(E17*10+2) -> 110 | H17: =VLOOKUP(F17,$C$42:$D$66,2,1) -> 0 | I17: =0.5*(H17=1)+1/(H17+1)*(H17>1) -> 0 | J17: =D17-1+0.5*(L17=0)+I17*L17 -> 4.5 | K17: =E17-0.5 -> 1.5 | L17: =(COUNTIFS($F16:$F$17,F17)+1)*(H17>1)+0 -> 0
C18: =Риск_калькулятор!D6 -> R2 | D18: =IF(AND(Риск_калькулятор!F6>$T$5,Риск_калькулятор!F6<$U$5),2,IF(AND(Риск_калькулятор!F6>$T$6,Риск_калькулятор!F6<$U$6),3,IF(AND(Риск_калькулятор!F6>$T$7,Риск_калькулятор!F6<$U$7),4,IF(Риск_калькулятор!F6>$T$8,5,1)))) -> 5 | E18: =IF(AND(Риск_калькулятор!M6>$X$5,Риск_калькулятор!M6<$Y$5),2,IF(AND(Риск_калькулятор!M6>$X$6,Риск_калькулятор!M6<$Y$6),3,IF(AND(Риск_калькулятор!M6>$X$7,Риск_калькулятор!M6<$Y$7),4,IF(Риск_калькулятор!M6>$X$8,5,1)))) -> 3 | F18: =D18*(E18*10+2) -> 160 | H18: =VLOOKUP(F18,$C$42:$D$66,2,1) -> 0 | I18: =0.5*(H18=1)+1/(H18+1)*(H18>1) -> 0 | J18: =D18-1+0.5*(L18=0)+I18*L18 -> 4.5 | K18: =E18-0.5 -> 2.5 | L18: =(COUNTIFS($F17:$F$17,F18)+1)*(H18>1)+0 -> 0
C19: =Риск_калькулятор!D7 -> R3 | D19: =IF(AND(Риск_калькулятор!F7>$T$5,Риск_калькулятор!F7<$U$5),2,IF(AND(Риск_калькулятор!F7>$T$6,Риск_калькулятор!F7<$U$6),3,IF(AND(Риск_калькулятор!F7>$T$7,Риск_калькулятор!F7<$U$7),4,IF(Риск_калькулятор!F7>$T$8,5,1)))) -> 4 | E19: =IF(AND(Риск_калькулятор!M7>$X$5,Риск_калькулятор!M7<$Y$5),2,IF(AND(Риск_калькулятор!M7>$X$6,Риск_калькулятор!M7<$Y$6),3,IF(AND(Риск_калькулятор!M7>$X$7,Риск_калькулятор!M7<$Y$7),4,IF(Риск_калькулятор!M7>$X$8,5,1)))) -> 4 | F19: =D19*(E19*10+2) -> 168 | H19: =VLOOKUP(F19,$C$42:$D$66,2,1) -> 1 | I19: =0.5*(H19=1)+1/(H19+1)*(H19>1) -> 0.5 | J19: =D19-1+0.5*(L19=0)+I19*L19 -> 3.5 | K19: =E19-0.5 -> 3.5 | L19: =(COUNTIFS($F$17:$F18,F19)+1)*(H19>1)+0 -> 0
C20: =Риск_калькулятор!D8 -> R4 | D20: =IF(AND(Риск_калькулятор!F8>$T$5,Риск_калькулятор!F8<$U$5),2,IF(AND(Риск_калькулятор!F8>$T$6,Риск_калькулятор!F8<$U$6),3,IF(AND(Риск_калькулятор!F8>$T$7,Риск_калькулятор!F8<$U$7),4,IF(Риск_калькулятор!F8>$T$8,5,1)))) -> 1 | E20: =IF(AND(Риск_калькулятор!M8>$X$5,Риск_калькулятор!M8<$Y$5),2,IF(AND(Риск_калькулятор!M8>$X$6,Риск_калькулятор!M8<$Y$6),3,IF(AND(Риск_калькулятор!M8>$X$7,Риск_калькулятор!M8<$Y$7),4,IF(Риск_калькулятор!M8>$X$8,5,1)))) -> 2 | F20: =D20*(E20*10+2) -> 22 | H20: =VLOOKUP(F20,$C$42:$D$66,2,1) -> 4 | I20: =0.5*(H20=1)+1/(H20+1)*(H20>1) -> 0.2 | J20: =D20-1+0.5*(L20=0)+I20*L20 -> 0.2 | K20: =E20-0.5 -> 1.5 | L20: =(COUNTIFS($F$17:$F19,F20)+1)*(H20>1)+0 -> 1
C21: =Риск_калькулятор!D9 -> R5 | D21: =IF(AND(Риск_калькулятор!F9>$T$5,Риск_калькулятор!F9<$U$5),2,IF(AND(Риск_калькулятор!F9>$T$6,Риск_калькулятор!F9<$U$6),3,IF(AND(Риск_калькулятор!F9>$T$7,Риск_калькулятор!F9<$U$7),4,IF(Риск_калькулятор!F9>$T$8,5,1)))) -> 1 | E21: =IF(AND(Риск_калькулятор!M9>$X$5,Риск_калькулятор!M9<$Y$5),2,IF(AND(Риск_калькулятор!M9>$X$6,Риск_калькулятор!M9<$Y$6),3,IF(AND(Риск_калькулятор!M9>$X$7,Риск_калькулятор!M9<$Y$7),4,IF(Риск_калькулятор!M9>$X$8,5,1)))) -> 2 | F21: =D21*(E21*10+2) -> 22 | H21: =VLOOKUP(F21,$C$42:$D$66,2,1) -> 4 | I21: =0.5*(H21=1)+1/(H21+1)*(H21>1) -> 0.2 | J21: =D21-1+0.5*(L21=0)+I21*L21 -> 0.4 | K21: =E21-0.5 -> 1.5 | L21: =(COUNTIFS($F$17:$F20,F21)+1)*(H21>1)+0 -> 2
C22: =Риск_калькулятор!D10 -> R6 | D22: =IF(AND(Риск_калькулятор!F10>$T$5,Риск_калькулятор!F10<$U$5),2,IF(AND(Риск_калькулятор!F10>$T$6,Риск_калькулятор!F10<$U$6),3,IF(AND(Риск_калькулятор!F10>$T$7,Риск_калькулятор!F10<$U$7),4,IF(Риск_калькулятор!F10>$T$8,5,1)))) -> 2 | E22: =IF(AND(Риск_калькулятор!M10>$X$5,Риск_калькулятор!M10<$Y$5),2,IF(AND(Риск_калькулятор!M10>$X$6,Риск_калькулятор!M10<$Y$6),3,IF(AND(Риск_калькулятор!M10>$X$7,Риск_калькулятор!M10<$Y$7),4,IF(Риск_калькулятор!M10>$X$8,5,1)))) -> 2 | F22: =D22*(E22*10+2) -> 44 | H22: =VLOOKUP(F22,$C$42:$D$66,2,1) -> 2 | I22: =0.5*(H22=1)+1/(H22+1)*(H22>1) -> 0.33333333 | J22: =D22-1+0.5*(L22=0)+I22*L22 -> 1.3333333 | K22: =E22-0.5 -> 1.5 | L22: =(COUNTIFS($F$17:$F21,F22)+1)*(H22>1)+0 -> 1
C23: =Риск_калькулятор!D11 -> R7 | D23: =IF(AND(Риск_калькулятор!F11>$T$5,Риск_калькулятор!F11<$U$5),2,IF(AND(Риск_калькулятор!F11>$T$6,Риск_калькулятор!F11<$U$6),3,IF(AND(Риск_калькулятор!F11>$T$7,Риск_калькулятор!F11<$U$7),4,IF(Риск_калькулятор!F11>$T$8,5,1)))) -> 3 | E23: =IF(AND(Риск_калькулятор!M11>$X$5,Риск_калькулятор!M11<$Y$5),2,IF(AND(Риск_калькулятор!M11>$X$6,Риск_калькулятор!M11<$Y$6),3,IF(AND(Риск_калькулятор!M11>$X$7,Риск_калькулятор!M11<$Y$7),4,IF(Риск_калькулятор!M11>$X$8,5,1)))) -> 2 | F23: =D23*(E23*10+2) -> 66 | H23: =VLOOKUP(F23,$C$42:$D$66,2,1) -> 1 | I23: =0.5*(H23=1)+1/(H23+1)*(H23>1) -> 0.5 | J23: =D23-1+0.5*(L23=0)+I23*L23 -> 2.5 | K23: =E23-0.5 -> 1.5 | L23: =(COUNTIFS($F$17:$F22,F23)+1)*(H23>1)+0 -> 0
C24: =Риск_калькулятор!D12 -> R8 | D24: =IF(AND(Риск_калькулятор!F12>$T$5,Риск_калькулятор!F12<$U$5),2,IF(AND(Риск_калькулятор!F12>$T$6,Риск_калькулятор!F12<$U$6),3,IF(AND(Риск_калькулятор!F12>$T$7,Риск_калькулятор!F12<$U$7),4,IF(Риск_калькулятор!F12>$T$8,5,1)))) -> 2 | E24: =IF(AND(Риск_калькулятор!M12>$X$5,Риск_калькулятор!M12<$Y$5),2,IF(AND(Риск_калькулятор!M12>$X$6,Риск_калькулятор!M12<$Y$6),3,IF(AND(Риск_калькулятор!M12>$X$7,Риск_калькулятор!M12<$Y$7),4,IF(Риск_калькулятор!M12>$X$8,5,1)))) -> 2 | F24: =D24*(E24*10+2) -> 44 | H24: =VLOOKUP(F24,$C$42:$D$66,2,1) -> 2 | I24: =0.5*(H24=1)+1/(H24+1)*(H24>1) -> 0.33333333 | J24: =D24-1+0.5*(L24=0)+I24*L24 -> 1.6666667 | K24: =E24-0.5 -> 1.5 | L24: =(COUNTIFS($F$17:$F23,F24)+1)*(H24>1)+0 -> 2
C25: =Риск_калькулятор!D13 -> R9 | D25: =IF(AND(Риск_калькулятор!F13>$T$5,Риск_калькулятор!F13<$U$5),2,IF(AND(Риск_калькулятор!F13>$T$6,Риск_калькулятор!F13<$U$6),3,IF(AND(Риск_калькулятор!F13>$T$7,Риск_калькулятор!F13<$U$7),4,IF(Риск_калькулятор!F13>$T$8,5,1)))) -> 1 | E25: =IF(AND(Риск_калькулятор!M13>$X$5,Риск_калькулятор!M13<$Y$5),2,IF(AND(Риск_калькулятор!M13>$X$6,Риск_калькулятор!M13<$Y$6),3,IF(AND(Риск_калькулятор!M13>$X$7,Риск_калькулятор!M13<$Y$7),4,IF(Риск_калькулятор!M13>$X$8,5,1)))) -> 2 | F25: =D25*(E25*10+2) -> 22 | H25: =VLOOKUP(F25,$C$42:$D$66,2,1) -> 4 | I25: =0.5*(H25=1)+1/(H25+1)*(H25>1) -> 0.2 | J25: =D25-1+0.5*(L25=0)+I25*L25 -> 0.6 | K25: =E25-0.5 -> 1.5 | L25: =(COUNTIFS($F$17:$F24,F25)+1)*(H25>1)+0 -> 3
C26: =Риск_калькулятор!D14 -> R10 | D26: =IF(AND(Риск_калькулятор!F14>$T$5,Риск_калькулятор!F14<$U$5),2,IF(AND(Риск_калькулятор!F14>$T$6,Риск_калькулятор!F14<$U$6),3,IF(AND(Риск_калькулятор!F14>$T$7,Риск_калькулятор!F14<$U$7),4,IF(Риск_калькулятор!F14>$T$8,5,1)))) -> 1 | E26: =IF(AND(Риск_калькулятор!M14>$X$5,Риск_калькулятор!M14<$Y$5),2,IF(AND(Риск_калькулятор!M14>$X$6,Риск_калькулятор!M14<$Y$6),3,IF(AND(Риск_калькулятор!M14>$X$7,Риск_калькулятор!M14<$Y$7),4,IF(Риск_калькулятор!M14>$X$8,5,1)))) -> 2 | F26: =D26*(E26*10+2) -> 22 | H26: =VLOOKUP(F26,$C$42:$D$66,2,1) -> 4 | I26: =0.5*(H26=1)+1/(H26+1)*(H26>1) -> 0.2 | J26: =D26-1+0.5*(L26=0)+I26*L26 -> 0.8 | K26: =E26-0.5 -> 1.5 | L26: =(COUNTIFS($F$17:$F25,F26)+1)*(H26>1)+0 -> 4
C34: 52 | D34: =$C34*$D$39 -> 52 | E34: =$C34*$E$39 -> 104 | F34: =$C34*$F$39 -> 156 | G34: =$C34*$G$39 -> 208 | H34: =$C34*$H$39 -> 260
C35: 42 | D35: =$C35*$D$39 -> 42 | E35: =$C35*$E$39 -> 84 | F35: =$C35*$F$39 -> 126 | G35: =$C35*$G$39 -> 168 | H35: =$C35*$H$39 -> 210
C36: 36 | D36: =$C36*$D$39 -> 36 | E36: =$C36*$E$39 -> 72 | F36: =$C36*$F$39 -> 108 | G36: =$C36*$G$39 -> 144 | H36: =$C36*$H$39 -> 180
C37: 22 | D37: =$C37*$D$39 -> 22 | E37: =$C37*$E$39 -> 44 | F37: =$C37*$F$39 -> 66 | G37: =$C37*$G$39 -> 88 | H37: =$C37*$H$39 -> 110
C38: 12 | D38: =$C38*$D$39 -> 12 | E38: =$C38*$E$39 -> 24 | F38: =$C38*$F$39 -> 36 | G38: =$C38*$G$39 -> 48 | H38: =$C38*$H$39 -> 60
D39: 1 | E39: 2 | F39: 3 | G39: 4 | H39: 5
C42: =D38 -> 12 | D42: =COUNTIFS($F$17:$F$26,C42) -> 0
C43: =E38 -> 24 | D43: =COUNTIFS($F$17:$F$26,C43) -> 0
C44: =F38 -> 36 | D44: =COUNTIFS($F$17:$F$26,C44) -> 0
C45: =G38 -> 48 | D45: =COUNTIFS($F$17:$F$26,C45) -> 0
C46: =H38 -> 60 | D46: =COUNTIFS($F$17:$F$26,C46) -> 0
C47: =D37 -> 22 | D47: =COUNTIFS($F$17:$F$26,C47) -> 4
C48: =E37 -> 44 | D48: =COUNTIFS($F$17:$F$26,C48) -> 2
C49: =F37 -> 66 | D49: =COUNTIFS($F$17:$F$26,C49) -> 1
C50: =G37 -> 88 | D50: =COUNTIFS($F$17:$F$26,C50) -> 0
...

Sheet ModelRiskSYS1

Sheet PMTable
A1: 1 | B1: Generated with the SIPmath™ Modeler Tools from ProbabilityManagement.org
B2: Index | C2: Risk_1 | D2: Risk_2 | E2: Risk_3 | F2: Risk_4 | G2: Risk_5 | H2: Risk_6 | I2: Risk_7 | J2: Risk_8 | K2: Risk_9 | L2: Risk_10 | M2: Total
B3: Values | C3: =Риск_калькулятор!$J$5 -> 61.316919 | D3: =Риск_калькулятор!$J$6 -> 0 | E3: =Риск_калькулятор!$J$7 -> 90.70199 | F3: =Риск_калькулятор!$J$8 -> 0 | G3: =Риск_калькулятор!$J$9 -> 0 | H3: =Риск_калькулятор!$J$10 -> 0 | I3: =Риск_калькулятор!$J$11 -> 0 | J3: =Риск_калькулятор!$J$12 -> 0 | K3: =Риск_калькулятор!$J$13 -> 0 | L3: =Риск_калькулятор!$J$14 -> 0 | M3: =Риск_калькулятор!$J$15 -> 0
B4: 1 | C4: 61.316919 | D4: 0 | E4: 90.70199 | F4: 0 | G4: 0 | H4: 0 | I4: 0 | J4: 0 | K4: 0 | L4: 0 | M4: 0
B5: 2 | C5: 44.823027 | D5: 60.138768 | E5: 83.911277 | F5: 59.459753 | G5: 0 | H5: 0 | I5: 0 | J5: 0 | K5: 48.409919 | L5: 0 | M5: 0
B6: 3 | C6: 55.1258 | D6: 0 | E6: 85.361254 | F6: 38.730018 | G6: 0 | H6: 60.027104 | I6: 48.521745 | J6: 0 | K6: 0 | L6: 0 | M6: 0
B7: 4 | C7: 11.475472 | D7: 0 | E7: 93.942021 | F7: 27.418057 | G7: 0 | H7: 52.518029 | I7: 0 | J7: 0 | K7: 63.093575 | L7: 0 | M7: 0
B8: 5 | C8: 31.563268 | D8: 66.622363 | E8: 117.73055 | F8: 0 | G8: 0 | H8: 0 | I8: 0 | J8: 0 | K8: 47.233539 | L8: 0 | M8: 0
B9: 6 | C9: 45.55641 | D9: 85.61142 | E9: 71.558358 | F9: 31.884113 | G9: 0 | H9: 0 | I9: 0 | J9: 0 | K9: 51.827843 | L9: 0 | M9: 0
B10: 7 | C10: 27.843142 | D10: 66.86407 | E10: 102.09464 | F10: 56.053376 | G10: 0 | H10: 0 | I10: 0 | J10: 0 | K10: 48.661178 | L10: 24.112354 | M10: 0
B11: 8 | C11: 28.592528 | D11: 78.340664 | E11: 81.892931 | F11: 0 | G11: 0 | H11: 0 | I11: 48.833861 | J11: 0 | K11: 44.383391 | L11: 0 | M11: 0
B12: 9 | C12: 50.823463 | D12: 84.063566 | E12: 104.55422 | F12: 40.53654 | G12: 0 | H12: 0 | I12: 0 | J12: 0 | K12: 0 | L12: 0 | M12: 0
B13: 10 | C13: 59.832489 | D13: 59.877283 | E13: 83.954046 | F13: 53.082471 | G13: 0 | H13: 0 | I13: 37.37265 | J13: 0 | K13: 18.733661 | L13: 0 | M13: 0
B14: 11 | C14: 61.345495 | D14: 81.667551 | E14: 78.098141 | F14: 66.262751 | G14: 0 | H14: 0 | I14: 0 | J14: 0 | K14: 28.53968 | L14: 0 | M14: 0
B15: 12 | C15: 58.903543 | D15: 56.497984 | E15: 0 | F15: 40.481701 | G15: 0 | H15: 32.46697 | I15: 58.749207 | J15: 0 | K15: 26.290522 | L15: 0 | M15: 0
... B1003: 1000 | C1003: 38.317542 | D1003: 70.093426 | E1003: 0 | F1003: 0 | G1003: 0 | H1003: 33.855791 | I1003: 0 | J1003: 41.218505 | K1003: 48.454955 | L1003: 0 | M1003: 0

Sheet SIPmath Chart Data
B1: Risk_1 | C1: Risk_2 | D1: Risk_3 | E1: Risk_4 | F1: Risk_5 | G1: Risk_6 | H1: Risk_7 | I1: Risk_8 | J1: Risk_9 | K1: Risk_10 | L1: Total
A2: Expected Value | B2: =ROUND( AVERAGE( Risk_1 ), $B$9 ) -> 39 | C2: =ROUND( AVERAGE( Risk_2 ), $C$9 ) -> 63 | D2: =ROUND( AVERAGE( Risk_3 ), $D$9 ) -> 68 | E2: =ROUND( AVERAGE( Risk_4 ), $E$9 ) -> 35 | F2: =ROUND( AVERAGE( Risk_5 ), $F$9 ) -> 5 | G2: =ROUND( AVERAGE( Risk_6 ), $G$9 ) -> 10 | H2: =ROUND( AVERAGE( Risk_7 ), $H$9 ) -> 18 | I2: =ROUND( AVERAGE( Risk_8 ), $I$9 ) -> 8 | J2: =ROUND( AVERAGE( Risk_9 ), $J$9 ) -> 36 | K2: =ROUND( AVERAGE( Risk_10 ), $K$9 ) -> 4 | L2: =ROUND( AVERAGE( Total ), $L$9 ) -> 0
A3: Series Name | B3: =$B$1 & " Avg " & $B$2 -> Risk_1 Avg 39 | C3: =$C$1 & " Avg " & $C$2 -> Risk_2 Avg 63 | D3: =$D$1 & " Avg " & $D$2 -> Risk_3 Avg 68 | E3: =$E$1 & " Avg " & $E$2 -> Risk_4 Avg 35 | F3: =$F$1 & " Avg " & $F$2 -> Risk_5 Avg 5 | G3: =$G$1 & " Avg " & $G$2 -> Risk_6 Avg 10 | H3: =$H$1 & " Avg " & $H$2 -> Risk_7 Avg 18 | I3: =$I$1 & " Avg " & $I$2 -> Risk_8 Avg 8 | J3: =$J$1 & " Avg " & $J$2 -> Risk_9 Avg 36 | K3: =$K$1 & " Avg " & $K$2 -> Risk_10 Avg 4 | L3: =$L$1 & " Avg " & $L$2 -> Total Avg 0
A4: Integer chart? | B4: FALSE | C4: FALSE | D4: FALSE | E4: FALSE | F4: FALSE | G4: FALSE | H4: FALSE | I4: FALSE | J4: FALSE | K4: FALSE | L4: FALSE
A5: Loss Exceedance | B5: FALSE | C5: FALSE | D5: FALSE | E5: FALSE | F5: FALSE | G5: FALSE | H5: FALSE | I5: FALSE | J5: FALSE | K5: FALSE | L5: FALSE
A6: Number of Bins | B6: =IF( $B$4, MIN( INT( MAX( Risk_1 ) - MIN( Risk_1 ) + 1 ), 10 ), 10 ) -> 10 | C6: =IF( $C$4, MIN( INT( MAX( Risk_2 ) - MIN( Risk_2 ) + 1 ), 10 ), 10 ) -> 10 | D6: =IF( $D$4, MIN( INT( MAX( Risk_3 ) - MIN( Risk_3 ) + 1 ), 10 ), 10 ) -> 10 | E6: =IF( $E$4, MIN( INT( MAX( Risk_4 ) - MIN( Risk_4 ) + 1 ), 10 ), 10 ) -> 10 | F6: =IF( $F$4, MIN( INT( MAX( Risk_5 ) - MIN( Risk_5 ) + 1 ), 10 ), 10 ) -> 10 | G6: =IF( $G$4, MIN( INT( MAX( Risk_6 ) - MIN( Risk_6 ) + 1 ), 10 ), 10 ) -> 10 | H6: =IF( $H$4, MIN( INT( MAX( Risk_7 ) - MIN( Risk_7 ) + 1 ), 10 ), 10 ) -> 10 | I6: =IF( $I$4, MIN( INT( MAX( Risk_8 ) - MIN( Risk_8 ) + 1 ), 10 ), 10 ) -> 10 | J6: =IF( $J$4, MIN( INT( MAX( Risk_9 ) - MIN( Risk_9 ) + 1 ), 10 ), 10 ) -> 10 | K6: =IF( $K$4, MIN( INT( MAX( Risk_10 ) - MIN( Risk_10 ) + 1 ), 10 ), 10 ) -> 10 | L6: =IF( $L$4, MIN( INT( MAX( Total ) - MIN( Total ) + 1 ), 10 ), 10 ) -> 10
A7: Label position | B7: 10 | C7: 10 | D7: 10 | E7: 10 | F7: 10 | G7: 10 | H7: 10 | I7: 10 | J7: 10 | K7: 10 | L7: 10
A8: Bin Width | B8: =ROUNDUP(( MAX( Risk_1 ) - $B$13 ) / $B$6, $B$9 ) -> 7 | C8: =ROUNDUP(( MAX( Risk_2 ) - $C$13 ) / $C$6, $C$9 ) -> 10 | D8: =ROUNDUP(( MAX( Risk_3 ) - $D$13 ) / $D$6, $D$9 ) -> 15 | E8: =ROUNDUP(( MAX( Risk_4 ) - $E$13 ) / $E$6, $E$9 ) -> 7 | F8: =ROUNDUP(( MAX( Risk_5 ) - $F$13 ) / $F$6, $F$9 ) -> 7 | G8: =ROUNDUP(( MAX( Risk_6 ) - $G$13 ) / $G$6, $G$9 ) -> 7 | H8: =ROUNDUP(( MAX( Risk_7 ) - $H$13 ) / $H$6, $H$9 ) -> 7 | I8: =ROUNDUP(( MAX( Risk_8 ) - $I$13 ) / $I$6, $I$9 ) -> 7 | J8: =ROUNDUP(( MAX( Risk_9 ) - $J$13 ) / $J$6, $J$9 ) -> 7 | K8: =ROUNDUP(( MAX( Risk_10 ) - $K$13 ) / $K$6, $K$9 ) -> 7 | L8: =ROUNDUP(( MAX( Total ) - $L$13 ) / $L$6, $L$9 ) -> 0
A9: Decimals | B9: 0 | C9: 0 | D9: 0 | E9: 0 | F9: 0 | G9: 0 | H9: 0 | I9: 0 | J9: 0 | K9: 0 | L9: 0
A10: Scale | B10: 1 | C10: 1 | D10: 1 | E10: 1 | F10: 1 | G10: 1 | H10: 1 | I10: 1 | J10: 1 | K10: 1 | L10: 1
A11: Use Axis Title? | B11: FALSE | C11: FALSE | D11: FALSE | E11: FALSE | F11: FALSE | G11: FALSE | H11: FALSE | I11: FALSE | J11: FALSE | K11: FALSE | L11: FALSE
A12: Axis Title | B12: =IF( AND( $B$11, $B$10 > 1 ), MID( TEXT( $B$10, "#,##0" ), IF( MOD( LEN( TEXT( $B$10, "0" )), 3 ) = 1, 3, 2), 100 ) & "s", "Axis Title" ) -> Axis Title | C12: =IF( AND( $C$11, $C$10 > 1 ), MID( TEXT( $C$10, "#,##0" ), IF( MOD( LEN( TEXT( $C$10, "0" )), 3 ) = 1, 3, 2), 100 ) & "s", "Axis Title" ) -> Axis Title | D12: =IF( AND( $D$11, $D$10 > 1 ), MID( TEXT( $D$10, "#,##0" ), IF( MOD( LEN( TEXT( $D$10, "0" )), 3 ) = 1, 3, 2), 100 ) & "s", "Axis Title" ) -> Axis Title | E12: =IF( AND( $E$11, $E$10 > 1 ), MID( TEXT( $E$10, "#,##0" ), IF( MOD( LEN( TEXT( $E$10, "0" )), 3 ) = 1, 3, 2), 100 ) & "s", "Axis Title" ) -> Axis Title | F12: =IF( AND( $F$11, $F$10 > 1 ), MID( TEXT( $F$10, "#,##0" ), IF( MOD( LEN( TEXT( $F$10, "0" )), 3 ) = 1, 3, 2), 100 ) & "s", "Axis Title" ) -> Axis Title | G12: =IF( AND( $G$11, $G$10 > 1 ), MID( TEXT( $G$10, "#,##0" ), IF( MOD( LEN( TEXT( $G$10, "0" )), 3 ) = 1, 3, 2), 100 ) & "s", "Axis Title" ) -> Axis Title | H12: =IF( AND( $H$11, $H$10 > 1 ), MID( TEXT( $H$10, "#,##0" ), IF( MOD( LEN( TEXT( $H$10, "0" )), 3 ) = 1, 3, 2), 100 ) & "s", "Axis Title" ) -> Axis Title | I12: =IF( AND( $I$11, $I$10 > 1 ), MID( TEXT( $I$10, "#,##0" ), IF( MOD( LEN( TEXT( $I$10, "0" )), 3 ) = 1, 3, 2), 100 ) & "s", "Axis Title" ) -> Axis Title | J12: =IF( AND( $J$11, $J$10 > 1 ), MID( TEXT( $J$10, "#,##0" ), IF( MOD( LEN( TEXT( $J$10, "0" )), 3 ) = 1, 3, 2), 100 ) & "s", "Axis Title" ) -> Axis Title | K12: =IF( AND( $K$11, $K$10 > 1 ), MID( TEXT( $K$10, "#,##0" ), IF( MOD( LEN( TEXT( $K$10, "0" )), 3 ) = 1, 3, 2), 100 ) & "s", "Axis Title" ) -> Axis Title | L12: =IF( AND( $L$11, $L$10 > 1 ), MID( TEXT( $L$10, "#,##0" ), IF( MOD( LEN( TEXT( $L$10, "0" )), 3 ) = 1, 3, 2), 100 ) & "s", "Axis Title" ) -> Axis Title
A13: Min | B13: =ROUND( MIN( Risk_1 ), $B$9 - LOG( $B$10 )) - IF( $B$4, 1, 0 ) -> 0 | C13: =ROUND( MIN( Risk_2 ), $C$9 - LOG( $C$10 )) - IF( $C$4, 1, 0 ) -> 0 | D13: =ROUND( MIN( Risk_3 ), $D$9 - LOG( $D$10 )) - IF( $D$4, 1, 0 ) -> 0 | E13: =ROUND( MIN( Risk_4 ), $E$9 - LOG( $E$10 )) - IF( $E$4, 1, 0 ) -> 0 | F13: =ROUND( MIN( Risk_5 ), $F$9 - LOG( $F$10 )) - IF( $F$4, 1, 0 ) -> 0 | G13: =ROUND( MIN( Risk_6 ), $G$9 - LOG( $G$10 )) - IF( $G$4, 1, 0 ) -> 0 | H13: =ROUND( MIN( Risk_7 ), $H$9 - LOG( $H$10 )) - IF( $H$4, 1, 0 ) -> 0 | I13: =ROUND( MIN( Risk_8 ), $I$9 - LOG( $I$10 )) - IF( $I$4, 1, 0 ) -> 0 | J13: =ROUND( MIN( Risk_9 ), $J$9 - LOG( $J$10 )) - IF( $J$4, 1, 0 ) -> 0 | K13: =ROUND( MIN( Risk_10 ), $K$9 - LOG( $K$10 )) - IF( $K$4, 1, 0 ) -> 0 | L13: =ROUND( MIN( Total ), $L$9 - LOG( $L$10 )) - IF( $L$4, 1, 0 ) -> 0
A14: Bin Range | B14: =ROUND( $B$13 + $B$8, $B$9 - LOG( $B$10 )) -> 7 | C14: =ROUND( $C$13 + $C$8, $C$9 - LOG( $C$10 )) -> 10 | D14: =ROUND( $D$13 + $D$8, $D$9 - LOG( $D$10 )) -> 15 | E14: =ROUND( $E$13 + $E$8, $E$9 - LOG( $E$10 )) -> 7 | F14: =ROUND( $F$13 + $F$8, $F$9 - LOG( $F$10 )) -> 7 | G14: =ROUND( $G$13 + $G$8, $G$9 - LOG( $G$10 )) -> 7 | H14: =ROUND( $H$13 + $H$8, $H$9 - LOG( $H$10 )) -> 7 | I14: =ROUND( $I$13 + $I$8, $I$9 - LOG( $I$10 )) -> 7 | J14: =ROUND( $J$13 + $J$8, $J$9 - LOG( $J$10 )) -> 7 | K14: =ROUND( $K$13 + $K$8, $K$9 - LOG( $K$10 )) -> 7 | L14: =ROUND( $L$13 + $L$8, $L$9 - LOG( $L$10 )) -> 0
A15: Frequency | B15: =ROUND( $B$14 + $B$8, $B$9 - LOG( $B$10 )) -> 14 | C15: =ROUND( $C$14 + $C$8, $C$9 - LOG( $C$10 )) -> 20 | D15: =ROUND( $D$14 + $D$8, $D$9 - LOG( $D$10 )) -> 30 | E15: =ROUND( $E$14 + $E$8, $E$9 - LOG( $E$10 )) -> 14 | F15: =ROUND( $F$14 + $F$8, $F$9 - LOG( $F$10 )) -> 14 | G15: =ROUND( $G$14 + $G$8, $G$9 - LOG( $G$10 )) -> 14 | H15: =ROUND( $H$14 + $H$8, $H$9 - LOG( $H$10 )) -> 14 | I15: =ROUND( $I$14 + $I$8, $I$9 - LOG( $I$10 )) -> 14 | J15: =ROUND( $J$14 + $J$8, $J$9 - LOG( $J$10 )) -> 14 | K15: =ROUND( $K$14 + $K$8, $K$9 - LOG( $K$10 )) -> 14 | L15: =ROUND( $L$14 + $L$8, $L$9 - LOG( $L$10 )) -> 0
A16: Labels | B16: =ROUND( $B$15 + $B$8, $B$9 - LOG( $B$10 )) -> 21 | C16: =ROUND( $C$15 + $C$8, $C$9 - LOG( $C$10 )) -> 30 | D16: =ROUND( $D$15 + $D$8, $D$9 - LOG( $D$10 )) -> 45 | E16: =ROUND( $E$15 + $E$8, $E$9 - LOG( $E$10 )) -> 21 | F16: =ROUND( $F$15 + $F$8, $F$9 - LOG( $F$10 )) -> 21 | G16: =ROUND( $G$15 + $G$8, $G$9 - LOG( $G$10 )) -> 21 | H16: =ROUND( $H$15 + $H$8, $H$9 - LOG( $H$10 )) -> 21 | I16: =ROUND( $I$15 + $I$8, $I$9 - LOG( $I$10 )) -> 21 | J16: =ROUND( $J$15 + $J$8, $J$9 - LOG( $J$10 )) -> 21 | K16: =ROUND( $K$15 + $K$8, $K$9 - LOG( $K$10 )) -> 21 | L16: =ROUND( $L$15 + $L$8, $L$9 - LOG( $L$10 )) -> 0
A17: Cumulative | B17: =ROUND( $B$16 + $B$8, $B$9 - LOG( $B$10 )) -> 28 | C17: =ROUND( $C$16 + $C$8, $C$9 - LOG( $C$10 )) -> 40 | D17: =ROUND( $D$16 + $D$8, $D$9 - LOG( $D$10 )) -> 60 | E17: =ROUND( $E$16 + $E$8, $E$9 - LOG( $E$10 )) -> 28 | F17: =ROUND( $F$16 + $F$8, $F$9 - LOG( $F$10 )) -> 28 | G17: =ROUND( $G$16 + $G$8, $G$9 - LOG( $G$10 )) -> 28 | H17: =ROUND( $H$16 + $H$8, $H$9 - LOG( $H$10 )) -> 28 | I17: =ROUND( $I$16 + $I$8, $I$9 - LOG( $I$10 )) -> 28 | J17: =ROUND( $J$16 + $J$8, $J$9 - LOG( $J$10 )) -> 28 | K17: =ROUND( $K$16 + $K$8, $K$9 - LOG( $K$10 )) -> 28 | L17: =ROUND( $L$16 + $L$8, $L$9 - LOG( $L$10 )) -> 0
B18: =ROUND( $B$17 + $B$8, $B$9 - LOG( $B$10 )) -> 35 | C18: =ROUND( $C$17 + $C$8, $C$9 - LOG( $C$10 )) -> 50 | D18: =ROUND( $D$17 + $D$8, $D$9 - LOG( $D$10 )) -> 75 | E18: =ROUND( $E$17 + $E$8, $E$9 - LOG( $E$10 )) -> 35 | F18: =ROUND( $F$17 + $F$8, $F$9 - LOG( $F$10 )) -> 35 | G18: =ROUND( $G$17 + $G$8, $G$9 - LOG( $G$10 )) -> 35 | H18: =ROUND( $H$17 + $H$8, $H$9 - LOG( $H$10 )) -> 35 | I18: =ROUND( $I$17 + $I$8, $I$9 - LOG( $I$10 )) -> 35 | J18: =ROUND( $J$17 + $J$8, $J$9 - LOG( $J$10 )) -> 35 | K18: =ROUND( $K$17 + $K$8, $K$9 - LOG( $K$10 )) -> 35 | L18: =ROUND( $L$17 + $L$8, $L$9 - LOG( $L$10 )) -> 0
B19: =ROUND( $B$18 + $B$8, $B$9 - LOG( $B$10 )) -> 42 | C19: =ROUND( $C$18 + $C$8, $C$9 - LOG( $C$10 )) -> 60 | D19: =ROUND( $D$18 + $D$8, $D$9 - LOG( $D$10 )) -> 90 | E19: =ROUND( $E$18 + $E$8, $E$9 - LOG( $E$10 )) -> 42 | F19: =ROUND( $F$18 + $F$8, $F$9 - LOG( $F$10 )) -> 42 | G19: =ROUND( $G$18 + $G$8, $G$9 - LOG( $G$10 )) -> 42 | H19: =ROUND( $H$18 + $H$8, $H$9 - LOG( $H$10 )) -> 42 | I19: =ROUND( $I$18 + $I$8, $I$9 - LOG( $I$10 )) -> 42 | J19: =ROUND( $J$18 + $J$8, $J$9 - LOG( $J$10 )) -> 42 | K19: =ROUND( $K$18 + $K$8, $K$9 - LOG( $K$10 )) -> 42 | L19: =ROUND( $L$18 + $L$8, $L$9 - LOG( $L$10 )) -> 0
B20: =ROUND( $B$19 + $B$8, $B$9 - LOG( $B$10 )) -> 49 | C20: =ROUND( $C$19 + $C$8, $C$9 - LOG( $C$10 )) -> 70 | D20: =ROUND( $D$19 + $D$8, $D$9 - LOG( $D$10 )) -> 105 | E20: =ROUND( $E$19 + $E$8, $E$9 - LOG( $E$10 )) -> 49 | F20: =ROUND( $F$19 + $F$8, $F$9 - LOG( $F$10 )) -> 49 | G20: =ROUND( $G$19 + $G$8, $G$9 - LOG( $G$10 )) -> 49 | H20: =ROUND( $H$19 + $H$8, $H$9 - LOG( $H$10 )) -> 49 | I20: =ROUND( $I$19 + $I$8, $I$9 - LOG( $I$10 )) -> 49 | J20: =ROUND( $J$19 + $J$8, $J$9 - LOG( $J$10 )) -> 49 | K20: =ROUND( $K$19 + $K$8, $K$9 - LOG( $K$10 )) -> 49 | L20: =ROUND( $L$19 + $L$8, $L$9 - LOG( $L$10 )) -> 0
B21: =ROUND( $B$20 + $B$8, $B$9 - LOG( $B$10 )) -> 56 | C21: =ROUND( $C$20 + $C$8, $C$9 - LOG( $C$10 )) -> 80 | D21: =ROUND( $D$20 + $D$8, $D$9 - LOG( $D$10 )) -> 120 | E21: =ROUND( $E$20 + $E$8, $E$9 - LOG( $E$10 )) -> 56 | F21: =ROUND( $F$20 + $F$8, $F$9 - LOG( $F$10 )) -> 56 | G21: =ROUND( $G$20 + $G$8, $G$9 - LOG( $G$10 )) -> 56 | H21: =ROUND( $H$20 + $H$8, $H$9 - LOG( $H$10 )) -> 56 | I21: =ROUND( $I$20 + $I$8, $I$9 - LOG( $I$10 )) -> 56 | J21: =ROUND( $J$20 + $J$8, $J$9 - LOG( $J$10 )) -> 56 | K21: =ROUND( $K$20 + $K$8, $K$9 - LOG( $K$10 )) -> 56 | L21: =ROUND( $L$20 + $L$8, $L$9 - LOG( $L$10 )) -> 0
B22: =ROUND( $B$21 + $B$8, $B$9 - LOG( $B$10 )) -> 63 | C22: =ROUND( $C$21 + $C$8, $C$9 - LOG( $C$10 )) -> 90 | D22: =ROUND( $D$21 + $D$8, $D$9 - LOG( $D$10 )) -> 135 | E22: =ROUND( $E$21 + $E$8, $E$9 - LOG( $E$10 )) -> 63 | F22: =ROUND( $F$21 + $F$8, $F$9 - LOG( $F$10 )) -> 63 | G22: =ROUND( $G$21 + $G$8, $G$9 - LOG( $G$10 )) -> 63 | H22: =ROUND( $H$21 + $H$8, $H$9 - LOG( $H$10 )) -> 63 | I22: =ROUND( $I$21 + $I$8, $I$9 - LOG( $I$10 )) -> 63 | J22: =ROUND( $J$21 + $J$8, $J$9 - LOG( $J$10 )) -> 63 | K22: =ROUND( $K$21 + $K$8, $K$9 - LOG( $K$10 )) -> 63 | L22: =ROUND( $L$21 + $L$8, $L$9 - LOG( $L$10 )) -> 0
B23: =ROUND( $B$22 + $B$8, $B$9 - LOG( $B$10 )) -> 70 | C23: =ROUND( $C$22 + $C$8, $C$9 - LOG( $C$10 )) -> 100 | D23: =ROUND( $D$22 + $D$8, $D$9 - LOG( $D$10 )) -> 150 | E23: =ROUND( $E$22 + $E$8, $E$9 - LOG( $E$10 )) -> 70 | F23: =ROUND( $F$22 + $F$8, $F$9 - LOG( $F$10 )) -> 70 | G23: =ROUND( $G$22 + $G$8, $G$9 - LOG( $G$10 )) -> 70 | H23: =ROUND( $H$22 + $H$8, $H$9 - LOG( $H$10 )) -> 70 | I23: =ROUND( $I$22 + $I$8, $I$9 - LOG( $I$10 )) -> 70 | J23: =ROUND( $J$22 + $J$8, $J$9 - LOG( $J$10 )) -> 70 | K23: =ROUND( $K$22 + $K$8, $K$9 - LOG( $K$10 )) -> 70 | L23: =ROUND( $L$22 + $L$8, $L$9 - LOG( $L$10 )) -> 0
B24: =ROUND( $B$23 + $B$8, $B$9 - LOG( $B$10 )) -> 77 | C24: =ROUND( $C$23 + $C$8, $C$9 - LOG( $C$10 )) -> 110 | D24: =ROUND( $D$23 + $D$8, $D$9 - LOG( $D$10 )) -> 165 | E24: =ROUND( $E$23 + $E$8, $E$9 - LOG( $E$10 )) -> 77 | F24: =ROUND( $F$23 + $F$8, $F$9 - LOG( $F$10 )) -> 77 | G24: =ROUND( $G$23 + $G$8, $G$9 - LOG( $G$10 )) -> 77 | H24: =ROUND( $H$23 + $H$8, $H$9 - LOG( $H$10 )) -> 77 | I24: =ROUND( $I$23 + $I$8, $I$9 - LOG( $I$10 )) -> 77 | J24: =ROUND( $J$23 + $J$8, $J$9 - LOG( $J$10 )) -> 77 | K24: =ROUND( $K$23 + $K$8, $K$9 - LOG( $K$10 )) -> 77 | L24: =ROUND( $L$23 + $L$8, $L$9 - LOG( $L$10 )) -> 0
B25: =ROUND( $B$24 + $B$8, $B$9 - LOG( $B$10 )) -> 84 | C25: =ROUND( $C$24 + $C$8, $C$9 - LOG( $C$10 )) -> 120 | D25: =ROUND( $D$24 + $D$8, $D$9 - LOG( $D$10 )) -> 180 | E25: =ROUND( $E$24 + $E$8, $E$9 - LOG( $E$10 )) -> 84 | F25: =ROUND( $F$24 + $F$8, $F$9 - LOG( $F$10 )) -> 84 | G25: =ROUND( $G$24 + $G$8, $G$9 - LOG( $G$10 )) -> 84 | H25: =ROUND( $H$24 + $H$8, $H$9 - LOG( $H$10 )) -> 84 | I25: =ROUND( $I$24 + $I$8, $I$9 - LOG( $I$10 )) -> 84 | J25: =ROUND( $J$24 + $J$8, $J$9 - LOG( $J$10 )) -> 84 | K25: =ROUND( $K$24 + $K$8, $K$9 - LOG( $K$10 )) -> 84 | L25: =ROUND( $L$24 + $L$8, $L$9 - LOG( $L$10 )) -> 0
B26: =ROUND( $B$25 + $B$8, $B$9 - LOG( $B$10 )) -> 91 | C26: =ROUND( $C$25 + $C$8, $C$9 - LOG( $C$10 )) -> 130 | D26: =ROUND( $D$25 + $D$8, $D$9 - LOG( $D$10 )) -> 195 | E26: =ROUND( $E$25 + $E$8, $E$9 - LOG( $E$10 )) -> 91 | F26: =ROUND( $F$25 + $F$8, $F$9 - LOG( $F$10 )) -> 91 | G26: =ROUND( $G$25 + $G$8, $G$9 - LOG( $G$10 )) -> 91 | H26: =ROUND( $H$25 + $H$8, $H$9 - LOG( $H$10 )) -> 91 | I26: =ROUND( $I$25 + $I$8, $I$9 - LOG( $I$10 )) -> 91 | J26: =ROUND( $J$25 + $J$8, $J$9 - LOG( $J$10 )) -> 91 | K26: =ROUND( $K$25 + $K$8, $K$9 - LOG( $K$10 )) -> 91 | L26: =ROUND( $L$25 + $L$8, $L$9 - LOG( $L$10 )) -> 0
B27: =ROUND( $B$26 + $B$8, $B$9 - LOG( $B$10 )) -> 98 | C27: =ROUND( $C$26 + $C$8, $C$9 - LOG( $C$10 )) -> 140 | D27: =ROUND( $D$26 + $D$8, $D$9 - LOG( $D$10 )) -> 210 | E27: =ROUND( $E$26 + $E$8, $E$9 - LOG( $E$10 )) -> 98 | F27: =ROUND( $F$26 + $F$8, $F$9 - LOG( $F$10 )) -> 98 | G27: =ROUND( $G$26 + $G$8, $G$9 - LOG( $G$10 )) -> 98 | H27: =ROUND( $H$26 + $H$8, $H$9 - LOG( $H$10 )) -> 98 | I27: =ROUND( $I$26 + $I$8, $I$9 - LOG( $I$10 )) -> 98 | J27: =ROUND( $J$26 + $J$8, $J$9 - LOG( $J$10 )) -> 98 | K27: =ROUND( $K$26 + $K$8, $K$9 - LOG( $K$10 )) -> 98 | L27: =ROUND( $L$26 + $L$8, $L$9 - LOG( $L$10 )) -> 0
B28: =ROUND( $B$27 + $B$8, $B$9 - LOG( $B$10 )) -> 105 | C28: =ROUND( $C$27 + $C$8, $C$9 - LOG( $C$10 )) -> 150 | D28: =ROUND( $D$27 + $D$8, $D$9 - LOG( $D$10 )) -> 225 | E28: =ROUND( $E$27 + $E$8, $E$9 - LOG( $E$10 )) -> 105 | F28: =ROUND( $F$27 + $F$8, $F$9 - LOG( $F$10 )) -> 105 | G28: =ROUND( $G$27 + $G$8, $G$9 - LOG( $G$10 )) -> 105 | H28: =ROUND( $H$27 + $H$8, $H$9 - LOG( $H$10 )) -> 105 | I28: =ROUND( $I$27 + $I$8, $I$9 - LOG( $I$10 )) -> 105 | J28: =ROUND( $J$27 + $J$8, $J$9 - LOG( $J$10 )) -> 105 | K28: =ROUND( $K$27 + $K$8, $K$9 - LOG( $K$10 )) -> 105 | L28: =ROUND( $L$27 + $L$8, $L$9 - LOG( $L$10 )) -> 0
B29: =ROUND( $B$28 + $B$8, $B$9 - LOG( $B$10 )) -> 112 | C29: =ROUND( $C$28 + $C$8, $C$9 - LOG( $C$10 )) -> 160 | D29: =ROUND( $D$28 + $D$8, $D$9 - LOG( $D$10 )) -> 240 | E29: =ROUND( $E$28 + $E$8, $E$9 - LOG( $E$10 )) -> 112 | F29: =ROUND( $F$28 + $F$8, $F$9 - LOG( $F$10 )) -> 112 | G29: =ROUND( $G$28 + $G$8, $G$9 - LOG( $G$10 )) -> 112 | H29: =ROUND( $H$28 + $H$8, $H$9 - LOG( $H$10 )) -> 112 | I29: =ROUND( $I$28 + $I$8, $I$9 - LOG( $I$10 )) -> 112 | J29: =ROUND( $J$28 + $J$8, $J$9 - LOG( $J$10 )) -> 112 | K29: =ROUND( $K$28 + $K$8, $K$9 - LOG( $K$10 )) -> 112 | L29: =ROUND( $L$28 + $L$8, $L$9 - LOG( $L$10 )) -> 0
B30: =ROUND( $B$29 + $B$8, $B$9 - LOG( $B$10 )) -> 119 | C30: =ROUND( $C$29 + $C$8, $C$9 - LOG( $C$10 )) -> 170 | D30: =ROUND( $D$29 + $D$8, $D$9 - LOG( $D$10 )) -> 255 | E30: =ROUND( $E$29 + $E$8, $E$9 - LOG( $E$10 )) -> 119 | F30: =ROUND( $F$29 + $F$8, $F$9 - LOG( $F$10 )) -> 119 | G30: =ROUND( $G$29 + $G$8, $G$9 - LOG( $G$10 )) -> 119 | H30: =ROUND( $H$29 + $H$8, $H$9 - LOG( $H$10 )) -> 119 | I30: =ROUND( $I$29 + $I$8, $I$9 - LOG( $I$10 )) -> 119 | J30: =ROUND( $J$29 + $J$8, $J$9 - LOG( $J$10 )) -> 119 | K30: =ROUND( $K$29 + $K$8, $K$9 - LOG( $K$10 )) -> 119 | L30: =ROUND( $L$29 + $L$8, $L$9 - LOG( $L$10 )) -> 0
B31: =ROUND( $B$30 + $B$8, $B$9 - LOG( $B$10 )) -> 126 | C31: =ROUND( $C$30 + $C$8, $C$9 - LOG( $C$10 )) -> 180 | D31: =ROUND( $D$30 + $D$8, $D$9 - LOG( $D$10 )) -> 270 | E31: =ROUND( $E$30 + $E$8, $E$9 - LOG( $E$10 )) -> 126 | F31: =ROUND( $F$30 + $F$8, $F$9 - LOG( $F$10 )) -> 126 | G31: =ROUND( $G$30 + $G$8, $G$9 - LOG( $G$10 )) -> 126 | H31: =ROUND( $H$30 + $H$8, $H$9 - LOG( $H$10 )) -> 126 | I31: =ROUND( $I$30 + $I$8, $I$9 - LOG( $I$10 )) -> 126 | J31: =ROUND( $J$30 + $J$8, $J$9 - LOG( $J$10 )) -> 126 | K31: =ROUND( $K$30 + $K$8, $K$9 - LOG( $K$10 )) -> 126 | L31: =ROUND( $L$30 + $L$8, $L$9 - LOG( $L$10 )) -> 0
B32: =ROUND( $B$31 + $B$8, $B$9 - LOG( $B$10 )) -> 133 | C32: =ROUND( $C$31 + $C$8, $C$9 - LOG( $C$10 )) -> 190 | D32: =ROUND( $D$31 + $D$8, $D$9 - LOG( $D$10 )) -> 285 | E32: =ROUND( $E$31 + $E$8, $E$9 - LOG( $E$10 )) -> 133 | F32: =ROUND( $F$31 + $F$8, $F$9 - LOG( $F$10 )) -> 133 | G32: =ROUND( $G$31 + $G$8, $G$9 - LOG( $G$10 )) -> 133 | H32: =ROUND( $H$31 + $H$8, $H$9 - LOG( $H$10 )) -> 133 | I32: =ROUND( $I$31 + $I$8, $I$9 - LOG( $I$10 )) -> 133 | J32: =ROUND( $J$31 + $J$8, $J$9 - LOG( $J$10 )) -> 133 | K32: =ROUND( $K$31 + $K$8, $K$9 - LOG( $K$10 )) -> 133 | L32: =ROUND( $L$31 + $L$8, $L$9 - LOG( $L$10 )) -> 0
B33: =ROUND( $B$32 + $B$8, $B$9 - LOG( $B$10 )) -> 140 | C33: =ROUND( $C$32 + $C$8, $C$9 - LOG( $C$10 )) -> 200 | D33: =ROUND( $D$32 + $D$8, $D$9 - LOG( $D$10 )) -> 300 | E33: =ROUND( $E$32 + $E$8, $E$9 - LOG( $E$10 )) -> 140 | F33: =ROUND( $F$32 + $F$8, $F$9 - LOG( $F$10 )) -> 140 | G33: =ROUND( $G$32 + $G$8, $G$9 - LOG( $G$10 )) -> 140 | H33: =ROUND( $H$32 + $H$8, $H$9 - LOG( $H$10 )) -> 140 | I33: =ROUND( $I$32 + $I$8, $I$9 - LOG( $I$10 )) -> 140 | J33: =ROUND( $J$32 + $J$8, $J$9 - LOG( $J$10 )) -> 140 | K33: =ROUND( $K$32 + $K$8, $K$9 - LOG( $K$10 )) -> 140 | L33: =ROUND( $L$32 + $L$8, $L$9 - LOG( $L$10 )) -> 0
B34: =ROUND( $B$33 + $B$8, $B$9 - LOG( $B$10 )) -> 147 | C34: =ROUND( $C$33 + $C$8, $C$9 - LOG( $C$10 )) -> 210 | D34: =ROUND( $D$33 + $D$8, $D$9 - LOG( $D$10 )) -> 315 | E34: =ROUND( $E$33 + $E$8, $E$9 - LOG( $E$10 )) -> 147 | F34: =ROUND( $F$33 + $F$8, $F$9 - LOG( $F$10 )) -> 147 | G34: =ROUND( $G$33 + $G$8, $G$9 - LOG( $G$10 )) -> 147 | H34: =ROUND( $H$33 + $H$8, $H$9 - LOG( $H$10 )) -> 147 | I34: =ROUND( $I$33 + $I$8, $I$9 - LOG( $I$10 )) -> 147 | J34: =ROUND( $J$33 + $J$8, $J$9 - LOG( $J$10 )) -> 147 | K34: =ROUND( $K$33 + $K$8, $K$9 - LOG( $K$10 )) -> 147 | L34: =ROUND( $L$33 + $L$8, $L$9 - LOG( $L$10 )) -> 0
B35: =ROUND( $B$34 + $B$8, $B$9 - LOG( $B$10 )) -> 154 | C35: =ROUND( $C$34 + $C$8, $C$9 - LOG( $C$10 )) -> 220 | D35: =ROUND( $D$34 + $D$8, $D$9 - LOG( $D$10 )) -> 330 | E35: =ROUND( $E$34 + $E$8, $E$9 - LOG( $E$10 )) -> 154 | F35: =ROUND( $F$34 + $F$8, $F$9 - LOG( $F$10 )) -> 154 | G35: =ROUND( $G$34 + $G$8, $G$9 - LOG( $G$10 )) -> 154 | H35: =ROUND( $H$34 + $H$8, $H$9 - LOG( $H$10 )) -> 154 | I35: =ROUND( $I$34 + $I$8, $I$9 - LOG( $I$10 )) -> 154 | J35: =ROUND( $J$34 + $J$8, $J$9 - LOG( $J$10 )) -> 154 | K35: =ROUND( $K$34 + $K$8, $K$9 - LOG( $K$10 )) -> 154 | L35: =ROUND( $L$34 + $L$8, $L$9 - LOG( $L$10 )) -> 0
B36: =ROUND( $B$35 + $B$8, $B$9 - LOG( $B$10 )) -> 161 | C36: =ROUND( $C$35 + $C$8, $C$9 - LOG( $C$10 )) -> 230 | D36: =ROUND( $D$35 + $D$8, $D$9 - LOG( $D$10 )) -> 345 | E36: =ROUND( $E$35 + $E$8, $E$9 - LOG( $E$10 )) -> 161 | F36: =ROUND( $F$35 + $F$8, $F$9 - LOG( $F$10 )) -> 161 | G36: =ROUND( $G$35 + $G$8, $G$9 - LOG( $G$10 )) -> 161 | H36: =ROUND( $H$35 + $H$8, $H$9 - LOG( $H$10 )) -> 161 | I36: =ROUND( $I$35 + $I$8, $I$9 - LOG( $I$10 )) -> 161 | J36: =ROUND( $J$35 + $J$8, $J$9 - LOG( $J$10 )) -> 161 | K36: =ROUND( $K$35 + $K$8, $K$9 - LOG( $K$10 )) -> 161 | L36: =ROUND( $L$35 + $L$8, $L$9 - LOG( $L$10 )) -> 0
B37: =ROUND( $B$36 + $B$8, $B$9 - LOG( $B$10 )) -> 168 | C37: =ROUND( $C$36 + $C$8, $C$9 - LOG( $C$10 )) -> 240 | D37: =ROUND( $D$36 + $D$8, $D$9 - LOG( $D$10 )) -> 360 | E37: =ROUND( $E$36 + $E$8, $E$9 - LOG( $E$10 )) -> 168 | F37: =ROUND( $F$36 + $F$8, $F$9 - LOG( $F$10 )) -> 168 | G37: =ROUND( $G$36 + $G$8, $G$9 - LOG( $G$10 )) -> 168 | H37: =ROUND( $H$36 + $H$8, $H$9 - LOG( $H$10 )) -> 168 | I37: =ROUND( $I$36 + $I$8, $I$9 - LOG( $I$10 )) -> 168 | J37: =ROUND( $J$36 + $J$8, $J$9 - LOG( $J$10 )) -> 168 | K37: =ROUND( $K$36 + $K$8, $K$9 - LOG( $K$10 )) -> 168 | L37: =ROUND( $L$36 + $L$8, $L$9 - LOG( $L$10 )) -> 0
B38: =ROUND( $B$37 + $B$8, $B$9 - LOG( $B$10 )) -> 175 | C38: =ROUND( $C$37 + $C$8, $C$9 - LOG( $C$10 )) -> 250 | D38: =ROUND( $D$37 + $D$8, $D$9 - LOG( $D$10 )) -> 375 | E38: =ROUND( $E$37 + $E$8, $E$9 - LOG( $E$10 )) -> 175 | F38: =ROUND( $F$37 + $F$8, $F$9 - LOG( $F$10 )) -> 175 | G38: =ROUND( $G$37 + $G$8, $G$9 - LOG( $G$10 )) -> 175 | H38: =ROUND( $H$37 + $H$8, $H$9 - LOG( $H$10 )) -> 175 | I38: =ROUND( $I$37 + $I$8, $I$9 - LOG( $I$10 )) -> 175 | J38: =ROUND( $J$37 + $J$8, $J$9 - LOG( $J$10 )) -> 175 | K38: =ROUND( $K$37 + $K$8, $K$9 - LOG( $K$10 )) -> 175 | L38: =ROUND( $L$37 + $L$8, $L$9 - LOG( $L$10 )) -> 0
B39: =ROUND( $B$38 + $B$8, $B$9 - LOG( $B$10 )) -> 182 | C39: =ROUND( $C$38 + $C$8, $C$9 - LOG( $C$10 )) -> 260 | D39: =ROUND( $D$38 + $D$8, $D$9 - LOG( $D$10 )) -> 390 | E39: =ROUND( $E$38 + $E$8, $E$9 - LOG( $E$10 )) -> 182 | F39: =ROUND( $F$38 + $F$8, $F$9 - LOG( $F$10 )) -> 182 | G39: =ROUND( $G$38 + $G$8, $G$9 - LOG( $G$10 )) -> 182 | H39: =ROUND( $H$38 + $H$8, $H$9 - LOG( $H$10 )) -> 182 | I39: =ROUND( $I$38 + $I$8, $I$9 - LOG( $I$10 )) -> 182 | J39: =ROUND( $J$38 + $J$8, $J$9 - LOG( $J$10 )) -> 182 | K39: =ROUND( $K$38 + $K$8, $K$9 - LOG( $K$10 )) -> 182 | L39: =ROUND( $L$38 + $L$8, $L$9 - LOG( $L$10 )) -> 0
B40: =ROUND( $B$39 + $B$8, $B$9 - LOG( $B$10 )) -> 189 | C40: =ROUND( $C$39 + $C$8, $C$9 - LOG( $C$10 )) -> 270 | D40: =ROUND( $D$39 + $D$8, $D$9 - LOG( $D$10 )) -> 405 | E40: =ROUND( $E$39 + $E$8, $E$9 - LOG( $E$10 )) -> 189 | F40: =ROUND( $F$39 + $F$8, $F$9 - LOG( $F$10 )) -> 189 | G40: =ROUND( $G$39 + $G$8, $G$9 - LOG( $G$10 )) -> 189 | H40: =ROUND( $H$39 + $H$8, $H$9 - LOG( $H$10 )) -> 189 | I40: =ROUND( $I$39 + $I$8, $I$9 - LOG( $I$10 )) -> 189 | J40: =ROUND( $J$39 + $J$8, $J$9 - LOG( $J$10 )) -> 189 | K40: =ROUND( $K$39 + $K$8, $K$9 - LOG( $K$10 )) -> 189 | L40: =ROUND( $L$39 + $L$8, $L$9 - LOG( $L$10 )) -> 0
...
